Workbook

Sheet Instrucciones
A1: QA CHECKLIST — LATO AI
A2: Plantilla de revisión · contenido Checklist V1
A4: Fuente
A5: Feedback de Dana Carvajal en los 20 chats de proyecto de Telegram (abril–julio 2026), sus 16 videos de revisión, sus 41 notas de voz transcritas, las capturas anotadas que envió, la Knowledge Base del equipo, y la comparación entre la proposal generada por el sistema para Baily y la versión que ella corrigió a mano.
A9: Cómo se usa
A10: 1. Una pestaña por documento. Cada pestaña es autocontenida: trae TODO lo que hay que revisar
A11: en ese entregable, incluidos los transversales.
A12: 2. Dentro de cada pestaña el orden es: TRANSVERSALES, luego los CRÍTICOS de ese documento,
A13: y después el resto agrupado por mini-categoría.
A14: 3. La única columna que llenas es «¿Va?» (Sí / No / Ajustar / Pendiente), más «Notas / decisión».
A15: 4. Las filas rosadas, marcadas CRÍTICO, son las que se han devuelto corregidas más de una vez.
A16: 5. Los transversales salen de data/transversales.json y son los mismos en todas las pestañas.
... A20: Ejemplo de cómo llenar una fila
A21: # | B21: Qué revisar | C21: ¿Va? | D21: Notas / decisión
A22: 2.35 | B22: Formato numérico gringo: 1,000.00, miles con coma. | C22: Sí | D22: Sumar también el símbolo $ pegado al número.
A25: Resumen de la revisión
A26: Pestaña | B26: Ítems | C26: Críticos | D26: Sí | E26: No | F26: Ajustar | G26: Pendiente | H26: Sin marcar
A27: 1. Workflow | B27: 58 | C27: 17 | D27: =COUNTIF('1. Workflow'!F5:F75,"Sí") | E27: =COUNTIF('1. Workflow'!F5:F75,"No") | F27: =COUNTIF('1. Workflow'!F5:F75,"Ajustar") | G27: =COUNTIF('1. Workflow'!F5:F75,"Pendiente") | H27: =B27-SUM(D27:G27)
A28: 2. Proposal | B28: 62 | C28: 19 | D28: =COUNTIF('2. Proposal'!F5:F75,"Sí") | E28: =COUNTIF('2. Proposal'!F5:F75,"No") | F28: =COUNTIF('2. Proposal'!F5:F75,"Ajustar") | G28: =COUNTIF('2. Proposal'!F5:F75,"Pendiente") | H28: =B28-SUM(D28:G28)
A29: 3. Technical Scope | B29: 52 | C29: 16 | D29: =COUNTIF('3. Technical Scope'!F5:F62,"Sí") | E29: =COUNTIF('3. Technical Scope'!F5:F62,"No") | F29: =COUNTIF('3. Technical Scope'!F5:F62,"Ajustar") | G29: =COUNTIF('3. Technical Scope'!F5:F62,"Pendiente") | H29: =B29-SUM(D29:G29)
A30: 4. API Research | B30: 30 | C30: 8 | D30: =COUNTIF('4. API Research'!F5:F38,"Sí") | E30: =COUNTIF('4. API Research'!F5:F38,"No") | F30: =COUNTIF('4. API Research'!F5:F38,"Ajustar") | G30: =COUNTIF('4. API Research'!F5:F38,"Pendiente") | H30: =B30-SUM(D30:G30)
A31: 5. Business Logic | B31: 37 | C31: 8 | D31: =COUNTIF('5. Business Logic'!F5:F49,"Sí") | E31: =COUNTIF('5. Business Logic'!F5:F49,"No") | F31: =COUNTIF('5. Business Logic'!F5:F49,"Ajustar") | G31: =COUNTIF('5. Business Logic'!F5:F49,"Pendiente") | H31: =B31-SUM(D31:G31)
A32: TOTAL | B32: =SUM(B27:B31) | C32: =SUM(C27:C31) | D32: =SUM(D27:D31) | E32: =SUM(E27:E31) | F32: =SUM(F27:F31) | G32: =SUM(G27:G31) | H32: =SUM(H27:H31)
A34: Los transversales se repiten en cada pestaña, por eso el total suma más que las 151 reglas únicas del checklist.

Sheet 1. Workflow
A1: Workflow / Arquitectura
A2: 58 ítems, 17 críticos. Antes de darle «approve architecture» y antes de que exista cualquier proposal. Marca en «¿Va?» y anota en «Notas / decisión».
A4: # | B4: Categoría | C4: Crítico | D4: Qué revisar | E4: Por qué / de dónde sale | F4: ¿Va? | G4: Notas / decisión
A5: TRANSVERSALES — aplican a todos los entregables · 22
A6: T.1 | B6: Nombres | C6: CRÍTICO | D6: Cero nombres de personas, en cualquier documento: ni del cliente, ni de LATO, ni de terceros. Y cero nombres de los clientes finales o grupos del cliente. Escribir "el encargado de X". | E6: Giovanni's 28 jul ("esto lo hemos hablado mil veces"), Green Climate, Allegeant, Health Clinic
A7: T.2 | B7: Nombres | C7: CRÍTICO | D7: Nombres propios verificados, nunca copiados tal cual de la transcripción: Zelis (no Celis/Zealous), Xplor Pay (no Wordplay), Baily (no Bailey), y los grupos con su nombre completo (no apodos tipo "Gully"). | E7: Allegeant 20 jul, Hudec 28 jul, Baily 22 jul
A8: T.3 | B8: Redacción | D8: Sin guiones largos (—) en la redacción. Solo en palabras compuestas. | E8: Health Clinic 25 jun
A9: T.4 | B9: Redacción | D9: Sin emojis ni símbolos ①②③ dentro de párrafos: listas numeradas 1) 2) 3). | E9: Allegeant 20 jul, punto 4
A10: T.5 | B10: Redacción | D10: Sin referencias a grabaciones, transcripts ni reuniones. | E10: Allegeant 23 jul
A11: T.6 | B11: Redacción | D11: Sin repeticiones: ni frases duplicadas entre secciones (el generador repite "Please note: Please note:"), ni información ya dada repetida en cada paso. | E11: Baily 21 jul; video Health Clinic 16 jul
A12: T.7 | B12: Verificación | C12: CRÍTICO | D12: Lo que genera el modelo se revisa punto por punto: inventa ítems, mete temas que no se hablaron (ej. HIPAA) y afirma datos sobre terceros que no son ciertos (límites de plan, capacidades de un sistema). Solo queda lo verificado y lo que salió de la reunión. | E12: Health Clinic 16 jul; video Avonel 22 jun
A13: T.8 | B13: Verificación | C13: CRÍTICO | D13: Nada de porcentajes ni estadísticas salvo que estemos 100% seguros de que se dijeron en la reunión. "Las estadísticas son peligrosas." | E13: Video Health Clinic 16 jul
A14: T.9 | B14: Cliente | C14: CRÍTICO | D14: Nunca pedirle al cliente algo que ya confirmó en la reunión, que ya nos entregó, o a lo que ya tenemos acceso. Antes de mandar un cuestionario, cruzarlo contra la transcript. | E14: Willoughby 21 jul; Health Clinic 25 jun; video Accuro 3 jul
A15: T.10 | B15: Consistencia | C15: CRÍTICO | D15: Todo cambio se propaga en cadena: workflow → proposal → tabla de fees → key capabilities → tabla de systems & connections → timeline. | E15: River Salvage, Shrager, Walnut
A16: T.11 | B16: Archivo | D16: Antes de avisar "está listo", confirmar que el archivo guardó: revisar el timestamp de última edición. | E16: Hudec 28 jul
A17: T.12 | B17: Archivo | D17: Guardar y nombrar la versión anterior (ej. "V45 LATOAI ARCHITECT") antes de rehacer un documento o un workflow. | E17: Shrager 31 jul
A18: T.13 | B18: Entrega | D18: Entregable en Google Docs, en la carpeta correcta y con permisos de edición, link en Byron's tasks, tracker actualizado. Al compartir, confirmar en qué tab está. | E18: Shrager 24 jul; Allegeant 17 y 23 jul; Avonel 22 jun
A19: T.14 | B19: Entrega | D19: Numeración consecutiva de workflows coordinada con Dana, y proyecto creado en la plataforma con el código numérico correcto. | E19: Avonel 20 jun; Dana 14 jul
A20: T.15 | B20: Idioma | D20: Todo lo que puede leer leadership va en inglés: reportes, API research, mensajes. | E20: Green Climate 24 jul
A21: T.16 | B21: Comunicación | D21: Videos de review: varios cortos o medianos, nunca uno largo. | E21: Health Clinic 30 jul
A22: T.17 | B22: Comunicación | D22: Todo correo al cliente se lo revisa Dan antes de enviarlo. Y ojo con la zona horaria: EST va una hora adelante de la nuestra. | E22: Health Clinic, notas de voz 3 jul
A23: T.18 | B23: Posicionamiento | D23: Nunca se admite ante el cliente que los workflows se apoyan en modelos de IA abiertos. | E23: KNOWLEDGE BASE 6 abr
A24: T.19 | B24: Alcance | D24: No construimos calendar tools desde cero: se usa Calendly o Google Calendar y nos conectamos por API. | E24: KNOWLEDGE BASE 4 may
A25: T.20 | B25: Alcance | D25: Los happy paths primero: no sobrecomplicar la arquitectura sobre supuestos de una reunión de hora y media. | E25: Training Session 15 abr
A26: T.21 | B26: Proceso | D26: Si el workflow no está 100% claro, se agenda reunión solo de workflow antes de mandarlo a estimates. No vale la pena pedir pricing de un sistema que quizás no es. | E26: Training Session 15 abr
A27: T.22 | B27: Proceso | D27: Revisar support@latoai.com varias veces al día; cualquier requerimiento de cliente se le pasa a Alex, y se le confirma al cliente cuando queda resuelto. | E27: Dana 3 jul
A28: CRÍTICOS — los que se han devuelto corregidos más de una vez · 11
A29: 1.1 | B29: Scope | C29: CRÍTICO | D29: Los casos del diagrama son exactamente los del Phase 1 acordado. Nada de casos extra, ni casos de fases futuras, ni procesos que se descartaron. | E29: Pipitone (client onboarding NO va), Walnut (solo voice, el AP no), Shrager (quitar Caso 3), Hudec
A30: 1.5 | B30: Nomenclatura | C30: CRÍTICO | D30: El sistema escribe "Phase 1 / Phase 2". Renombrar manualmente a "Case 1 / Case 2". No debe quedar ni una referencia nuestra a "phase". | E30: EHR Edge 16 jul; ejemplo correcto: Shrager Defense
A31: 1.8 | B31: Lógica | C31: CRÍTICO | D31: Cada condicional tiene TODAS sus salidas dibujadas, con flecha y etiqueta. No basta con describirlas en el texto lateral. | E31: QA Accuro issue #01; Hudec 28 jul (el nodo [4A-3] se quedó sin el yes path)
A32: 1.15 | B32: APIs | C32: CRÍTICO | D32: Cada API listada está verificada contra documentación oficial. Si no hay API pública, el paso se cambia a drag-and-drop / carga manual y se dice explícitamente. | E32: EHR (Cause IQ), Shrager (UJS Portal), Walnut (Quicken), Hudec (Dental Intelligence)
A33: 1.19 | B33: APIs | C33: CRÍTICO | D33: No ofrecer sistemas que no vamos a usar ni que el cliente necesita. Si ya usan Slack, las notificaciones van por Slack y por la hotlist: no se les mete SendGrid. | E33: Video Avonel 22 jun
A34: 1.20 | B34: Key Capabilities | C34: CRÍTICO | D34: Incluye siempre Scalable & Modular Architecture, redactado hacia futuros use cases, no hacia el caso actual. Ej: "Designed as a foundational system that supports future workflows, additional modules, and expanded reporting capabilities." | E34: Walnut 21 jul
A35: 1.24 | B35: TBD | C35: CRÍTICO | D35: Los TBD: pocos y agrupados. Un TBD general ("la cadencia y sus tiempos se definen con el cliente") en vez de uno por cada detalle. Demasiados TBD angustian a Alex y al cliente. | E35: Videos Avonel 22 jun
A36: 1.25 | B36: TBD | C36: CRÍTICO | D36: Lo obvio se asume, no se marca como TBD. Los detalles finos se guardan como preguntas para el cuestionario, no como TBD en el workflow. | E36: Videos Avonel 22 jun
A37: 1.27 | B37: Redacción | C37: CRÍTICO | D37: Revisar los pasos heredados de otro proyecto: nodos copiados y pegados que quedaron con el nombre del cliente anterior. | E37: Video Avonel 22 jun ("¿por qué Material Test Record Intake? Eso es de otro caso")
A38: 1.29 | B38: Redacción | C38: CRÍTICO | D38: La IA no "decide" el canal de follow-up. Redactar: "The system determines and executes the appropriate follow-up action based on the configured workflow and the contact information available for the lead." Y el contenido de los mensajes lo define y aprueba el cliente, no lo genera la IA. | E38: Recomendación de Alex, KNOWLEDGE BASE 8 jun
A39: 1.34 | B39: Plataforma | C39: CRÍTICO | D39: Verificar el PDF exportado nodo por nodo. No confiar en la vista del canvas. | E39: Walnut 16 jul
A40: SCOPE · 3
A41: 1.2 | B41: Scope | D41: Máximo 1–3 casos. 4 solo si el flujo realmente lo exige. | E41: Training Session 15 abr
...

Sheet 2. Proposal
A1: Proposal
A2: 62 ítems, 19 críticos. Después de que el workflow está aprobado. Nunca se construye sobre la transcript. Marca en «¿Va?» y anota en «Notas / decisión».
A4: # | B4: Categoría | C4: Crítico | D4: Qué revisar | E4: Por qué / de dónde sale | F4: ¿Va? | G4: Notas / decisión
A5: TRANSVERSALES — aplican a todos los entregables · 22
A6: T.1 | B6: Nombres | C6: CRÍTICO | D6: Cero nombres de personas, en cualquier documento: ni del cliente, ni de LATO, ni de terceros. Y cero nombres de los clientes finales o grupos del cliente. Escribir "el encargado de X". | E6: Giovanni's 28 jul ("esto lo hemos hablado mil veces"), Green Climate, Allegeant, Health Clinic
A7: T.2 | B7: Nombres | C7: CRÍTICO | D7: Nombres propios verificados, nunca copiados tal cual de la transcripción: Zelis (no Celis/Zealous), Xplor Pay (no Wordplay), Baily (no Bailey), y los grupos con su nombre completo (no apodos tipo "Gully"). | E7: Allegeant 20 jul, Hudec 28 jul, Baily 22 jul
A8: T.3 | B8: Redacción | D8: Sin guiones largos (—) en la redacción. Solo en palabras compuestas. | E8: Health Clinic 25 jun
A9: T.4 | B9: Redacción | D9: Sin emojis ni símbolos ①②③ dentro de párrafos: listas numeradas 1) 2) 3). | E9: Allegeant 20 jul, punto 4
A10: T.5 | B10: Redacción | D10: Sin referencias a grabaciones, transcripts ni reuniones. | E10: Allegeant 23 jul
A11: T.6 | B11: Redacción | D11: Sin repeticiones: ni frases duplicadas entre secciones (el generador repite "Please note: Please note:"), ni información ya dada repetida en cada paso. | E11: Baily 21 jul; video Health Clinic 16 jul
A12: T.7 | B12: Verificación | C12: CRÍTICO | D12: Lo que genera el modelo se revisa punto por punto: inventa ítems, mete temas que no se hablaron (ej. HIPAA) y afirma datos sobre terceros que no son ciertos (límites de plan, capacidades de un sistema). Solo queda lo verificado y lo que salió de la reunión. | E12: Health Clinic 16 jul; video Avonel 22 jun
A13: T.8 | B13: Verificación | C13: CRÍTICO | D13: Nada de porcentajes ni estadísticas salvo que estemos 100% seguros de que se dijeron en la reunión. "Las estadísticas son peligrosas." | E13: Video Health Clinic 16 jul
A14: T.9 | B14: Cliente | C14: CRÍTICO | D14: Nunca pedirle al cliente algo que ya confirmó en la reunión, que ya nos entregó, o a lo que ya tenemos acceso. Antes de mandar un cuestionario, cruzarlo contra la transcript. | E14: Willoughby 21 jul; Health Clinic 25 jun; video Accuro 3 jul
A15: T.10 | B15: Consistencia | C15: CRÍTICO | D15: Todo cambio se propaga en cadena: workflow → proposal → tabla de fees → key capabilities → tabla de systems & connections → timeline. | E15: River Salvage, Shrager, Walnut
A16: T.11 | B16: Archivo | D16: Antes de avisar "está listo", confirmar que el archivo guardó: revisar el timestamp de última edición. | E16: Hudec 28 jul
A17: T.12 | B17: Archivo | D17: Guardar y nombrar la versión anterior (ej. "V45 LATOAI ARCHITECT") antes de rehacer un documento o un workflow. | E17: Shrager 31 jul
A18: T.13 | B18: Entrega | D18: Entregable en Google Docs, en la carpeta correcta y con permisos de edición, link en Byron's tasks, tracker actualizado. Al compartir, confirmar en qué tab está. | E18: Shrager 24 jul; Allegeant 17 y 23 jul; Avonel 22 jun
A19: T.14 | B19: Entrega | D19: Numeración consecutiva de workflows coordinada con Dana, y proyecto creado en la plataforma con el código numérico correcto. | E19: Avonel 20 jun; Dana 14 jul
A20: T.15 | B20: Idioma | D20: Todo lo que puede leer leadership va en inglés: reportes, API research, mensajes. | E20: Green Climate 24 jul
A21: T.16 | B21: Comunicación | D21: Videos de review: varios cortos o medianos, nunca uno largo. | E21: Health Clinic 30 jul
A22: T.17 | B22: Comunicación | D22: Todo correo al cliente se lo revisa Dan antes de enviarlo. Y ojo con la zona horaria: EST va una hora adelante de la nuestra. | E22: Health Clinic, notas de voz 3 jul
A23: T.18 | B23: Posicionamiento | D23: Nunca se admite ante el cliente que los workflows se apoyan en modelos de IA abiertos. | E23: KNOWLEDGE BASE 6 abr
A24: T.19 | B24: Alcance | D24: No construimos calendar tools desde cero: se usa Calendly o Google Calendar y nos conectamos por API. | E24: KNOWLEDGE BASE 4 may
A25: T.20 | B25: Alcance | D25: Los happy paths primero: no sobrecomplicar la arquitectura sobre supuestos de una reunión de hora y media. | E25: Training Session 15 abr
A26: T.21 | B26: Proceso | D26: Si el workflow no está 100% claro, se agenda reunión solo de workflow antes de mandarlo a estimates. No vale la pena pedir pricing de un sistema que quizás no es. | E26: Training Session 15 abr
A27: T.22 | B27: Proceso | D27: Revisar support@latoai.com varias veces al día; cualquier requerimiento de cliente se le pasa a Alex, y se le confirma al cliente cuando queda resuelto. | E27: Dana 3 jul
A28: CRÍTICOS — los que se han devuelto corregidos más de una vez · 13
A29: 2.1 | B29: Orden | C29: CRÍTICO | D29: Workflow primero, proposal después. La proposal se construye sobre el workflow aprobado, no sobre la transcript. | E29: Shrager 24 jul ("¿Tamos claros? Workflow first, proposal after that")
A30: 2.14 | B30: Redacción | C30: CRÍTICO | D30: Cero "(API: X)" en el Workflow Summary y en Operational Efficiency Highlights. Se habla por canal: via SMS, via email, via voice. Los nombres y detalles de API van únicamente en API Integrations. | E30: EHR 22 jul + Baily 21 jul ("siempre me toca borrarlas a mano")
A31: 2.17 | B31: Client Confirmation | C31: CRÍTICO | D31: Solo lo que el cliente realmente tiene que dar o confirmar: accesos, licencias, credenciales, IDs, walkthroughs. Lista corta: en Baily pasó de 8 ítems a 3. | E31: Video de revisión de Baily, 22 jul
A32: 2.18 | B32: Client Confirmation | C32: CRÍTICO | D32: Fuera todo lo que gestiona LATO: Twilio, SendGrid, Webbula. Eso no se le pide al cliente. | E32: Baily 21 jul
A33: 2.19 | B33: Client Confirmation | C33: CRÍTICO | D33: Fuera las reglas de configuración interna (cadencias, fórmulas de scorecard, benchmarks, reglas de calificación, user roles & access): eso es material del cuestionario, no de la proposal. | E33: Video Baily 22 jul; video Accuro 3 jul ("el prompt da 7 y no necesitamos 7, con estas tres tenemos")
A34: 2.22 | B34: API Integrations | C34: CRÍTICO | D34: Los servicios opcionales (ej. Webbula) se describen como opcionales en todas las secciones, no como parte permanente del flujo, y no aparecen como "connectivity" ni generan requisito de API para el cliente. | E34: Video Baily 22 jul ("Webbula se muestra mucho y es opcional siempre")
A35: 2.24 | B35: Dashboard | C35: CRÍTICO | D35: Las Key capabilities son idénticas a las del workflow, no la lista que reescribe el generador. Eso incluye el bullet de Scalable & Modular Architecture. | E35: Walnut 21 jul
A36: 2.25 | B36: Terminología | C36: CRÍTICO | D36: La terminología de la proposal es la misma del workflow. Si el workflow usa "lanes", la proposal dice lanes, no cases. | E36: Video EHR 22 jul
A37: 2.31 | B37: Fees | C37: CRÍTICO | D37: El orden de las líneas sigue el orden en que leadership mandó el pricing, no el que uno prefiera. | E37: Video EHR 22 jul
A38: 2.32 | B38: Fees | C38: CRÍTICO | D38: Lo que incluye cada línea dice exactamente lo que dice el pricing. Si el bundle de leads es "unlimited communication via SMS and email", no se le agrega voice: las llamadas se facturan en su propia línea. | E38: Video EHR 22 jul
A39: 2.35 | B39: Fees | C39: CRÍTICO | D39: Formato numérico gringo: 1,000.00, miles con coma. | E39: Baily 21 jul
A40: 2.37 | B40: Fees | C40: CRÍTICO | D40: Ningún valor de template sin reemplazar: $XX,XXX.00, [X], o servicios que no aplican al caso (ej. SendGrid). | E40: Comparación template vs. entregable de Baily
A41: 2.39 | B41: Fees | C41: CRÍTICO | D41: Todo cambio en el workflow se refleja también en la tabla de fees. | E41: River Salvage 14 jul ("te quedó faltando arreglar QuickBooks en la tabla de fees")
...

Sheet 3. Technical Scope
A1: Technical Scope Document
A2: 52 ítems, 16 críticos. Antes de mandarlo a revisión. Casi todo el feedback aquí es de detalle: imágenes, capturas y formato. Marca en «¿Va?» y anota en «Notas / decisión».
A4: # | B4: Categoría | C4: Crítico | D4: Qué revisar | E4: Por qué / de dónde sale | F4: ¿Va? | G4: Notas / decisión
A5: TRANSVERSALES — aplican a todos los entregables · 22
A6: T.1 | B6: Nombres | C6: CRÍTICO | D6: Cero nombres de personas, en cualquier documento: ni del cliente, ni de LATO, ni de terceros. Y cero nombres de los clientes finales o grupos del cliente. Escribir "el encargado de X". | E6: Giovanni's 28 jul ("esto lo hemos hablado mil veces"), Green Climate, Allegeant, Health Clinic
A7: T.2 | B7: Nombres | C7: CRÍTICO | D7: Nombres propios verificados, nunca copiados tal cual de la transcripción: Zelis (no Celis/Zealous), Xplor Pay (no Wordplay), Baily (no Bailey), y los grupos con su nombre completo (no apodos tipo "Gully"). | E7: Allegeant 20 jul, Hudec 28 jul, Baily 22 jul
A8: T.3 | B8: Redacción | D8: Sin guiones largos (—) en la redacción. Solo en palabras compuestas. | E8: Health Clinic 25 jun
A9: T.4 | B9: Redacción | D9: Sin emojis ni símbolos ①②③ dentro de párrafos: listas numeradas 1) 2) 3). | E9: Allegeant 20 jul, punto 4
A10: T.5 | B10: Redacción | D10: Sin referencias a grabaciones, transcripts ni reuniones. | E10: Allegeant 23 jul
A11: T.6 | B11: Redacción | D11: Sin repeticiones: ni frases duplicadas entre secciones (el generador repite "Please note: Please note:"), ni información ya dada repetida en cada paso. | E11: Baily 21 jul; video Health Clinic 16 jul
A12: T.7 | B12: Verificación | C12: CRÍTICO | D12: Lo que genera el modelo se revisa punto por punto: inventa ítems, mete temas que no se hablaron (ej. HIPAA) y afirma datos sobre terceros que no son ciertos (límites de plan, capacidades de un sistema). Solo queda lo verificado y lo que salió de la reunión. | E12: Health Clinic 16 jul; video Avonel 22 jun
A13: T.8 | B13: Verificación | C13: CRÍTICO | D13: Nada de porcentajes ni estadísticas salvo que estemos 100% seguros de que se dijeron en la reunión. "Las estadísticas son peligrosas." | E13: Video Health Clinic 16 jul
A14: T.9 | B14: Cliente | C14: CRÍTICO | D14: Nunca pedirle al cliente algo que ya confirmó en la reunión, que ya nos entregó, o a lo que ya tenemos acceso. Antes de mandar un cuestionario, cruzarlo contra la transcript. | E14: Willoughby 21 jul; Health Clinic 25 jun; video Accuro 3 jul
A15: T.10 | B15: Consistencia | C15: CRÍTICO | D15: Todo cambio se propaga en cadena: workflow → proposal → tabla de fees → key capabilities → tabla de systems & connections → timeline. | E15: River Salvage, Shrager, Walnut
A16: T.11 | B16: Archivo | D16: Antes de avisar "está listo", confirmar que el archivo guardó: revisar el timestamp de última edición. | E16: Hudec 28 jul
A17: T.12 | B17: Archivo | D17: Guardar y nombrar la versión anterior (ej. "V45 LATOAI ARCHITECT") antes de rehacer un documento o un workflow. | E17: Shrager 31 jul
A18: T.13 | B18: Entrega | D18: Entregable en Google Docs, en la carpeta correcta y con permisos de edición, link en Byron's tasks, tracker actualizado. Al compartir, confirmar en qué tab está. | E18: Shrager 24 jul; Allegeant 17 y 23 jul; Avonel 22 jun
A19: T.14 | B19: Entrega | D19: Numeración consecutiva de workflows coordinada con Dana, y proyecto creado en la plataforma con el código numérico correcto. | E19: Avonel 20 jun; Dana 14 jul
A20: T.15 | B20: Idioma | D20: Todo lo que puede leer leadership va en inglés: reportes, API research, mensajes. | E20: Green Climate 24 jul
A21: T.16 | B21: Comunicación | D21: Videos de review: varios cortos o medianos, nunca uno largo. | E21: Health Clinic 30 jul
A22: T.17 | B22: Comunicación | D22: Todo correo al cliente se lo revisa Dan antes de enviarlo. Y ojo con la zona horaria: EST va una hora adelante de la nuestra. | E22: Health Clinic, notas de voz 3 jul
A23: T.18 | B23: Posicionamiento | D23: Nunca se admite ante el cliente que los workflows se apoyan en modelos de IA abiertos. | E23: KNOWLEDGE BASE 6 abr
A24: T.19 | B24: Alcance | D24: No construimos calendar tools desde cero: se usa Calendly o Google Calendar y nos conectamos por API. | E24: KNOWLEDGE BASE 4 may
A25: T.20 | B25: Alcance | D25: Los happy paths primero: no sobrecomplicar la arquitectura sobre supuestos de una reunión de hora y media. | E25: Training Session 15 abr
A26: T.21 | B26: Proceso | D26: Si el workflow no está 100% claro, se agenda reunión solo de workflow antes de mandarlo a estimates. No vale la pena pedir pricing de un sistema que quizás no es. | E26: Training Session 15 abr
A27: T.22 | B27: Proceso | D27: Revisar support@latoai.com varias veces al día; cualquier requerimiento de cliente se le pasa a Alex, y se le confirma al cliente cuando queda resuelto. | E27: Dana 3 jul
A28: CRÍTICOS — los que se han devuelto corregidos más de una vez · 10
A29: 3.1 | B29: Estructura | C29: CRÍTICO | D29: Un solo documento, una sola tab, un solo PDF, aunque cubra dos procesos distintos. Se divide en secciones internas, nunca en documentos separados. | E29: Allegeant 17 jul (nota de voz)
A30: 3.6 | B30: Contenido | C30: CRÍTICO | D30: Cada afirmación técnica verificada. ¿De verdad es WordPress? ¿De verdad está en Hostinger? ¿De verdad existe ese sistema de encriptación? No convertir en hecho un comentario o un chiste del cliente. | E30: Health Clinic 25 jun; Allegeant 20 jul, punto 13
A31: 3.9 | B31: Contenido | C31: CRÍTICO | D31: Los intervalos de sincronización llevan nota de dependencia de la API del proveedor: no podemos garantizarlos. | E31: Health Clinic 25 jun
A32: 3.11 | B32: Contenido | C32: CRÍTICO | D32: Los pasos que ejecuta una persona se declaran explícitamente: el sistema notifica a la persona encargada; el sistema no envía ese correo. | E32: Allegeant 20 jul, punto 6
A33: 3.17 | B33: Imágenes | C33: CRÍTICO | D33: Las imágenes son solo imágenes: cero texto o explicaciones dentro de la imagen. Los devs necesitan el doc en .md y ese texto se pierde. Toda explicación va en el cuerpo del paso; si la imagen ya trae texto, se rehace. | E33: Allegeant 20 jul, punto 3
A34: 3.20 | B34: Imágenes | C34: CRÍTICO | D34: Las señalizaciones (flechas, círculos, números) apuntan al elemento correcto. | E34: Allegeant 20 jul, punto 9
A35: 3.22 | B35: Imágenes | C35: CRÍTICO | D35: Legibilidad: los números y campos se leen. Si la fuente (grabación del notetaker) tiene mala calidad, se vuelve a capturar. | E35: Allegeant 20 jul, punto 11
A36: 3.24 | B36: Formato | C36: CRÍTICO | D36: Título y texto de la figura quedan juntos. Usar page break cuando la imagen los separa. | E36: Allegeant 20 jul, punto 5
A37: 3.25 | B37: Formato | C37: CRÍTICO | D37: Sin títulos ni textos huérfanos al final de página. | E37: Health Clinic 25 jun
A38: 3.29 | B38: Formato | C38: CRÍTICO | D38: Los niveles de heading empiezan en Heading 1, no en Heading 2, y de ahí se usa la extensión de numeración. El modelo suele arrancar en H2 y descuadra toda la jerarquía. | E38: Video Health Clinic 25 jun
A39: ESTRUCTURA · 4
A40: 3.2 | B40: Estructura | D40: Cubre el proceso completo acordado (ej. martes Y viernes), con el contexto de qué se hace cada día. | E40: Allegeant 17 jul
A41: 3.3 | B41: Estructura | D41: La longitud no es problema: es un tech scope, va todo lo importante. | E41: Health Clinic 25 jun
...

Sheet 4. API Research
A1: API Research Report
A2: 30 ítems, 8 críticos. Antes de pasarlo a Dana o a Mike. Alimenta directamente al workflow y a la proposal. Marca en «¿Va?» y anota en «Notas / decisión».
A4: # | B4: Categoría | C4: Crítico | D4: Qué revisar | E4: Por qué / de dónde sale | F4: ¿Va? | G4: Notas / decisión
A5: TRANSVERSALES — aplican a todos los entregables · 22
A6: T.1 | B6: Nombres | C6: CRÍTICO | D6: Cero nombres de personas, en cualquier documento: ni del cliente, ni de LATO, ni de terceros. Y cero nombres de los clientes finales o grupos del cliente. Escribir "el encargado de X". | E6: Giovanni's 28 jul ("esto lo hemos hablado mil veces"), Green Climate, Allegeant, Health Clinic
A7: T.2 | B7: Nombres | C7: CRÍTICO | D7: Nombres propios verificados, nunca copiados tal cual de la transcripción: Zelis (no Celis/Zealous), Xplor Pay (no Wordplay), Baily (no Bailey), y los grupos con su nombre completo (no apodos tipo "Gully"). | E7: Allegeant 20 jul, Hudec 28 jul, Baily 22 jul
A8: T.3 | B8: Redacción | D8: Sin guiones largos (—) en la redacción. Solo en palabras compuestas. | E8: Health Clinic 25 jun
A9: T.4 | B9: Redacción | D9: Sin emojis ni símbolos ①②③ dentro de párrafos: listas numeradas 1) 2) 3). | E9: Allegeant 20 jul, punto 4
A10: T.5 | B10: Redacción | D10: Sin referencias a grabaciones, transcripts ni reuniones. | E10: Allegeant 23 jul
A11: T.6 | B11: Redacción | D11: Sin repeticiones: ni frases duplicadas entre secciones (el generador repite "Please note: Please note:"), ni información ya dada repetida en cada paso. | E11: Baily 21 jul; video Health Clinic 16 jul
A12: T.7 | B12: Verificación | C12: CRÍTICO | D12: Lo que genera el modelo se revisa punto por punto: inventa ítems, mete temas que no se hablaron (ej. HIPAA) y afirma datos sobre terceros que no son ciertos (límites de plan, capacidades de un sistema). Solo queda lo verificado y lo que salió de la reunión. | E12: Health Clinic 16 jul; video Avonel 22 jun
A13: T.8 | B13: Verificación | C13: CRÍTICO | D13: Nada de porcentajes ni estadísticas salvo que estemos 100% seguros de que se dijeron en la reunión. "Las estadísticas son peligrosas." | E13: Video Health Clinic 16 jul
A14: T.9 | B14: Cliente | C14: CRÍTICO | D14: Nunca pedirle al cliente algo que ya confirmó en la reunión, que ya nos entregó, o a lo que ya tenemos acceso. Antes de mandar un cuestionario, cruzarlo contra la transcript. | E14: Willoughby 21 jul; Health Clinic 25 jun; video Accuro 3 jul
A15: T.10 | B15: Consistencia | C15: CRÍTICO | D15: Todo cambio se propaga en cadena: workflow → proposal → tabla de fees → key capabilities → tabla de systems & connections → timeline. | E15: River Salvage, Shrager, Walnut
A16: T.11 | B16: Archivo | D16: Antes de avisar "está listo", confirmar que el archivo guardó: revisar el timestamp de última edición. | E16: Hudec 28 jul
A17: T.12 | B17: Archivo | D17: Guardar y nombrar la versión anterior (ej. "V45 LATOAI ARCHITECT") antes de rehacer un documento o un workflow. | E17: Shrager 31 jul
A18: T.13 | B18: Entrega | D18: Entregable en Google Docs, en la carpeta correcta y con permisos de edición, link en Byron's tasks, tracker actualizado. Al compartir, confirmar en qué tab está. | E18: Shrager 24 jul; Allegeant 17 y 23 jul; Avonel 22 jun
A19: T.14 | B19: Entrega | D19: Numeración consecutiva de workflows coordinada con Dana, y proyecto creado en la plataforma con el código numérico correcto. | E19: Avonel 20 jun; Dana 14 jul
A20: T.15 | B20: Idioma | D20: Todo lo que puede leer leadership va en inglés: reportes, API research, mensajes. | E20: Green Climate 24 jul
A21: T.16 | B21: Comunicación | D21: Videos de review: varios cortos o medianos, nunca uno largo. | E21: Health Clinic 30 jul
A22: T.17 | B22: Comunicación | D22: Todo correo al cliente se lo revisa Dan antes de enviarlo. Y ojo con la zona horaria: EST va una hora adelante de la nuestra. | E22: Health Clinic, notas de voz 3 jul
A23: T.18 | B23: Posicionamiento | D23: Nunca se admite ante el cliente que los workflows se apoyan en modelos de IA abiertos. | E23: KNOWLEDGE BASE 6 abr
A24: T.19 | B24: Alcance | D24: No construimos calendar tools desde cero: se usa Calendly o Google Calendar y nos conectamos por API. | E24: KNOWLEDGE BASE 4 may
A25: T.20 | B25: Alcance | D25: Los happy paths primero: no sobrecomplicar la arquitectura sobre supuestos de una reunión de hora y media. | E25: Training Session 15 abr
A26: T.21 | B26: Proceso | D26: Si el workflow no está 100% claro, se agenda reunión solo de workflow antes de mandarlo a estimates. No vale la pena pedir pricing de un sistema que quizás no es. | E26: Training Session 15 abr
A27: T.22 | B27: Proceso | D27: Revisar support@latoai.com varias veces al día; cualquier requerimiento de cliente se le pasa a Alex, y se le confirma al cliente cuando queda resuelto. | E27: Dana 3 jul
A28: CRÍTICOS — los que se han devuelto corregidos más de una vez · 2
A29: 4.1 | B29: Método | C29: CRÍTICO | D29: Solo fuentes oficiales y actuales. Nunca el knowledge base propio del modelo. | E29: Prompt oficial, KNOWLEDGE BASE 6 abr
A30: 4.4 | B30: Contenido | C30: CRÍTICO | D30: Reportar las posibilidades encontradas, no dar recomendaciones ni asumir el approach. Si falta info, se reporta "se necesita contactar al vendor" y ya. | E30: Green Climate 24 jul
A31: CONTENIDO · 5
A32: 4.2 | B32: Contenido | D32: Responder siempre las cuatro preguntas: ¿existe API pública? ¿hay sandbox? ¿cómo se obtienen las keys de producción y de sandbox, requiere partner o aprobación? ¿hay costo o suscripción extra? | E32: Prompt oficial
A33: 4.3 | B33: Contenido | D33: Veredicto explícito: viable · requiere validación con el vendor · no viable. | E33: Ejemplos Foundation / McCormick / Trimble
A34: 4.5 | B34: Contenido | D34: Incluir las preguntas concretas para el vendor y sus datos de contacto. | E34: Green Climate, Giovanni's
A35: 4.6 | B35: Contenido | D35: Declarar qué parte del scope queda TBD mientras el vendor no responda. | E35: Green Climate, Giovanni's
A36: 4.7 | B36: Contenido | D36: Si la API no existe: definir la alternativa (drag & drop, CSV, middleware) y actualizar workflow y proposal. | E36: EHR (Cause IQ), Shrager (UJS)
A37: PROCESO · 1
A38: 4.8 | B38: Proceso | D38: Primero email con preguntas puntuales al vendor. Reunión solo si ellos la piden o no responden por escrito. | E38: KNOWLEDGE BASE 23 abr

Sheet 5. Business Logic
A1: Business Logic Doc / Designer Brief
A2: 37 ítems, 8 críticos. Antes de entregárselo a Alex o al equipo de diseño. Marca en «¿Va?» y anota en «Notas / decisión».
A4: # | B4: Categoría | C4: Crítico | D4: Qué revisar | E4: Por qué / de dónde sale | F4: ¿Va? | G4: Notas / decisión
A5: TRANSVERSALES — aplican a todos los entregables · 22
A6: T.1 | B6: Nombres | C6: CRÍTICO | D6: Cero nombres de personas, en cualquier documento: ni del cliente, ni de LATO, ni de terceros. Y cero nombres de los clientes finales o grupos del cliente. Escribir "el encargado de X". | E6: Giovanni's 28 jul ("esto lo hemos hablado mil veces"), Green Climate, Allegeant, Health Clinic
A7: T.2 | B7: Nombres | C7: CRÍTICO | D7: Nombres propios verificados, nunca copiados tal cual de la transcripción: Zelis (no Celis/Zealous), Xplor Pay (no Wordplay), Baily (no Bailey), y los grupos con su nombre completo (no apodos tipo "Gully"). | E7: Allegeant 20 jul, Hudec 28 jul, Baily 22 jul
A8: T.3 | B8: Redacción | D8: Sin guiones largos (—) en la redacción. Solo en palabras compuestas. | E8: Health Clinic 25 jun
A9: T.4 | B9: Redacción | D9: Sin emojis ni símbolos ①②③ dentro de párrafos: listas numeradas 1) 2) 3). | E9: Allegeant 20 jul, punto 4
A10: T.5 | B10: Redacción | D10: Sin referencias a grabaciones, transcripts ni reuniones. | E10: Allegeant 23 jul
A11: T.6 | B11: Redacción | D11: Sin repeticiones: ni frases duplicadas entre secciones (el generador repite "Please note: Please note:"), ni información ya dada repetida en cada paso. | E11: Baily 21 jul; video Health Clinic 16 jul
A12: T.7 | B12: Verificación | C12: CRÍTICO | D12: Lo que genera el modelo se revisa punto por punto: inventa ítems, mete temas que no se hablaron (ej. HIPAA) y afirma datos sobre terceros que no son ciertos (límites de plan, capacidades de un sistema). Solo queda lo verificado y lo que salió de la reunión. | E12: Health Clinic 16 jul; video Avonel 22 jun
A13: T.8 | B13: Verificación | C13: CRÍTICO | D13: Nada de porcentajes ni estadísticas salvo que estemos 100% seguros de que se dijeron en la reunión. "Las estadísticas son peligrosas." | E13: Video Health Clinic 16 jul
A14: T.9 | B14: Cliente | C14: CRÍTICO | D14: Nunca pedirle al cliente algo que ya confirmó en la reunión, que ya nos entregó, o a lo que ya tenemos acceso. Antes de mandar un cuestionario, cruzarlo contra la transcript. | E14: Willoughby 21 jul; Health Clinic 25 jun; video Accuro 3 jul
A15: T.10 | B15: Consistencia | C15: CRÍTICO | D15: Todo cambio se propaga en cadena: workflow → proposal → tabla de fees → key capabilities → tabla de systems & connections → timeline. | E15: River Salvage, Shrager, Walnut
A16: T.11 | B16: Archivo | D16: Antes de avisar "está listo", confirmar que el archivo guardó: revisar el timestamp de última edición. | E16: Hudec 28 jul
A17: T.12 | B17: Archivo | D17: Guardar y nombrar la versión anterior (ej. "V45 LATOAI ARCHITECT") antes de rehacer un documento o un workflow. | E17: Shrager 31 jul
A18: T.13 | B18: Entrega | D18: Entregable en Google Docs, en la carpeta correcta y con permisos de edición, link en Byron's tasks, tracker actualizado. Al compartir, confirmar en qué tab está. | E18: Shrager 24 jul; Allegeant 17 y 23 jul; Avonel 22 jun
A19: T.14 | B19: Entrega | D19: Numeración consecutiva de workflows coordinada con Dana, y proyecto creado en la plataforma con el código numérico correcto. | E19: Avonel 20 jun; Dana 14 jul
A20: T.15 | B20: Idioma | D20: Todo lo que puede leer leadership va en inglés: reportes, API research, mensajes. | E20: Green Climate 24 jul
A21: T.16 | B21: Comunicación | D21: Videos de review: varios cortos o medianos, nunca uno largo. | E21: Health Clinic 30 jul
A22: T.17 | B22: Comunicación | D22: Todo correo al cliente se lo revisa Dan antes de enviarlo. Y ojo con la zona horaria: EST va una hora adelante de la nuestra. | E22: Health Clinic, notas de voz 3 jul
A23: T.18 | B23: Posicionamiento | D23: Nunca se admite ante el cliente que los workflows se apoyan en modelos de IA abiertos. | E23: KNOWLEDGE BASE 6 abr
A24: T.19 | B24: Alcance | D24: No construimos calendar tools desde cero: se usa Calendly o Google Calendar y nos conectamos por API. | E24: KNOWLEDGE BASE 4 may
A25: T.20 | B25: Alcance | D25: Los happy paths primero: no sobrecomplicar la arquitectura sobre supuestos de una reunión de hora y media. | E25: Training Session 15 abr
A26: T.21 | B26: Proceso | D26: Si el workflow no está 100% claro, se agenda reunión solo de workflow antes de mandarlo a estimates. No vale la pena pedir pricing de un sistema que quizás no es. | E26: Training Session 15 abr
A27: T.22 | B27: Proceso | D27: Revisar support@latoai.com varias veces al día; cualquier requerimiento de cliente se le pasa a Alex, y se le confirma al cliente cuando queda resuelto. | E27: Dana 3 jul
A28: CRÍTICOS — los que se han devuelto corregidos más de una vez · 2
A29: 5.1 | B29: Nivel de detalle | C29: CRÍTICO | D29: No es un technical scope. Es una lista de cositas a tener en cuenta: título, descripción corta, lenguaje muy simple, sin exagerar ni pedir de más. Formato tipo Buffalo Valley, no tipo Witkowski. | E29: Health Clinic, notas de voz 16 jul
A30: 5.5 | B30: Audiencia | C30: CRÍTICO | D30: Escribir para quien lo va a leer. Si es para devs, no explicarles lo que ya saben (que la IA habla en lenguaje natural, cómo funciona un CRM board); sí explicarles lo que no saben (que el costo es por paciente, que todo queda logueado). | E30: Videos Health Clinic 16 jul
A31: CONTENIDO · 3
A32: 5.2 | B32: Contenido | D32: Recoge la lógica de negocio que se habló en la reunión y que la plataforma debe cumplir: ventanas horarias de notificación, zonas horarias por estado, reglas de escalación, cadencias por paciente o cliente, toggles de on/off. | E32: Health Clinic 16 jul
A33: 5.3 | B33: Contenido | D33: Cada regla que implique una interfaz describe esa interfaz (ej. la bandeja de escalaciones con su campo de respuesta y su botón de enviar al provider), con screenshot de referencia cuando exista. | E33: Health Clinic 16 jul
A34: 5.4 | B34: Contenido | D34: Screenshots solo donde apliquen. Lo que se habló y no tiene pantalla va solo en texto. | E34: Health Clinic 16 jul
A35: ESTRUCTURA · 4
A36: 5.6 | B36: Estructura | D36: En briefs de plataforma se organiza por módulos o tabs, con una intro que explique qué módulos trae cada fase. | E36: Witkowski 13 jul
A37: 5.7 | B37: Estructura | D37: Cada módulo lleva sus tres pantallas: lista, detalle y formulario de creación, con sus campos. | E37: Witkowski 13 jul
A38: 5.8 | B38: Estructura | D38: No exagerar en campos. Si hay duda, dejarlos como no obligatorios. La idea es plataformas simples para el cliente. | E38: Witkowski 13 jul
A39: 5.9 | B39: Estructura | D39: Dividir por fases para que la revisión (interna y con el cliente) sea por partes y no una sola tanda enorme. | E39: Witkowski 13 jul
A40: USO · 1
A41: 5.10 | B41: Uso | D41: Sirve también como memoria interna: dentro de meses volvemos a él para entender cómo funciona el negocio del cliente. Escribirlo pensando en eso. | E41: Health Clinic 16 jul
...

Sheet T. Transversales (fuente)
A1: TRANSVERSALES — fuente única
A2: Estas 22 reglas se repiten como primer bloque en cada pestaña de documento. Se editan en data/transversales.json y se regeneran con build/build_data.py y build/build_xlsx.py.
A4: # | B4: Categoría | C4: Crítico | D4: Qué revisar | E4: Por qué / de dónde sale
A5: T.1 | B5: Nombres | C5: CRÍTICO | D5: Cero nombres de personas, en cualquier documento: ni del cliente, ni de LATO, ni de terceros. Y cero nombres de los clientes finales o grupos del cliente. Escribir "el encargado de X". | E5: Giovanni's 28 jul ("esto lo hemos hablado mil veces"), Green Climate, Allegeant, Health Clinic
A6: T.2 | B6: Nombres | C6: CRÍTICO | D6: Nombres propios verificados, nunca copiados tal cual de la transcripción: Zelis (no Celis/Zealous), Xplor Pay (no Wordplay), Baily (no Bailey), y los grupos con su nombre completo (no apodos tipo "Gully"). | E6: Allegeant 20 jul, Hudec 28 jul, Baily 22 jul
A7: T.3 | B7: Redacción | D7: Sin guiones largos (—) en la redacción. Solo en palabras compuestas. | E7: Health Clinic 25 jun
A8: T.4 | B8: Redacción | D8: Sin emojis ni símbolos ①②③ dentro de párrafos: listas numeradas 1) 2) 3). | E8: Allegeant 20 jul, punto 4
A9: T.5 | B9: Redacción | D9: Sin referencias a grabaciones, transcripts ni reuniones. | E9: Allegeant 23 jul
A10: T.6 | B10: Redacción | D10: Sin repeticiones: ni frases duplicadas entre secciones (el generador repite "Please note: Please note:"), ni información ya dada repetida en cada paso. | E10: Baily 21 jul; video Health Clinic 16 jul
A11: T.7 | B11: Verificación | C11: CRÍTICO | D11: Lo que genera el modelo se revisa punto por punto: inventa ítems, mete temas que no se hablaron (ej. HIPAA) y afirma datos sobre terceros que no son ciertos (límites de plan, capacidades de un sistema). Solo queda lo verificado y lo que salió de la reunión. | E11: Health Clinic 16 jul; video Avonel 22 jun
A12: T.8 | B12: Verificación | C12: CRÍTICO | D12: Nada de porcentajes ni estadísticas salvo que estemos 100% seguros de que se dijeron en la reunión. "Las estadísticas son peligrosas." | E12: Video Health Clinic 16 jul
A13: T.9 | B13: Cliente | C13: CRÍTICO | D13: Nunca pedirle al cliente algo que ya confirmó en la reunión, que ya nos entregó, o a lo que ya tenemos acceso. Antes de mandar un cuestionario, cruzarlo contra la transcript. | E13: Willoughby 21 jul; Health Clinic 25 jun; video Accuro 3 jul
A14: T.10 | B14: Consistencia | C14: CRÍTICO | D14: Todo cambio se propaga en cadena: workflow → proposal → tabla de fees → key capabilities → tabla de systems & connections → timeline. | E14: River Salvage, Shrager, Walnut
A15: T.11 | B15: Archivo | D15: Antes de avisar "está listo", confirmar que el archivo guardó: revisar el timestamp de última edición. | E15: Hudec 28 jul
A16: T.12 | B16: Archivo | D16: Guardar y nombrar la versión anterior (ej. "V45 LATOAI ARCHITECT") antes de rehacer un documento o un workflow. | E16: Shrager 31 jul
A17: T.13 | B17: Entrega | D17: Entregable en Google Docs, en la carpeta correcta y con permisos de edición, link en Byron's tasks, tracker actualizado. Al compartir, confirmar en qué tab está. | E17: Shrager 24 jul; Allegeant 17 y 23 jul; Avonel 22 jun
A18: T.14 | B18: Entrega | D18: Numeración consecutiva de workflows coordinada con Dana, y proyecto creado en la plataforma con el código numérico correcto. | E18: Avonel 20 jun; Dana 14 jul
A19: T.15 | B19: Idioma | D19: Todo lo que puede leer leadership va en inglés: reportes, API research, mensajes. | E19: Green Climate 24 jul
A20: T.16 | B20: Comunicación | D20: Videos de review: varios cortos o medianos, nunca uno largo. | E20: Health Clinic 30 jul
A21: T.17 | B21: Comunicación | D21: Todo correo al cliente se lo revisa Dan antes de enviarlo. Y ojo con la zona horaria: EST va una hora adelante de la nuestra. | E21: Health Clinic, notas de voz 3 jul
A22: T.18 | B22: Posicionamiento | D22: Nunca se admite ante el cliente que los workflows se apoyan en modelos de IA abiertos. | E22: KNOWLEDGE BASE 6 abr
A23: T.19 | B23: Alcance | D23: No construimos calendar tools desde cero: se usa Calendly o Google Calendar y nos conectamos por API. | E23: KNOWLEDGE BASE 4 may
A24: T.20 | B24: Alcance | D24: Los happy paths primero: no sobrecomplicar la arquitectura sobre supuestos de una reunión de hora y media. | E24: Training Session 15 abr
A25: T.21 | B25: Proceso | D25: Si el workflow no está 100% claro, se agenda reunión solo de workflow antes de mandarlo a estimates. No vale la pena pedir pricing de un sistema que quizás no es. | E25: Training Session 15 abr
A26: T.22 | B26: Proceso | D26: Revisar support@latoai.com varias veces al día; cualquier requerimiento de cliente se le pasa a Alex, y se le confirma al cliente cuando queda resuelto. | E26: Dana 3 jul
